<?xml version="1.0"?>

<robot
    xmlns:sensor="http://playerstage.sourceforge.net/gazebo/xmlschema/#sensor"
    xmlns:controller="http://playerstage.sourceforge.net/gazebo/xmlschema/#controller"
    xmlns:interface="http://playerstage.sourceforge.net/gazebo/xmlschema/#interface">
  
  <!-- Properties (Constants) -->
  <property name="M_PI" value="3.14159"/>
  <property name="wheel_radius" value="0.11"/>
  <property name="wheel_length" value="0.096"/>
  <property name="wheel_mass" value="2.26796185"/> <!--assuming 5lbs -->
  
  <macro name="mcp_wheel" params="suffix parent shift_x shift_y">
    
    <joint name="${parent}_${suffix}_wheel_joint" type="continuous">
      <origin xyz="${shift_x} ${shift_y} -0.15" rpy="0 0 0"/>
      <axis xyz="0 1 0" />
      <parent link="${parent}" />
      <child link="${parent}_${suffix}_wheel_link" />
    </joint>
    
    <link name="${parent}_${suffix}_wheel_link">
      <visual>
        <origin xyz="0 0 0" rpy="${M_PI/2} 0 0"/>
        <geometry>
          <cylinder length="${wheel_length}" radius="${wheel_radius}"/>
        </geometry>
      </visual>
      
      <inertial>
        <mass value="${wheel_mass}"/>
        <inertia ixx="1.0" ixy="0.0" ixz="0.0" iyy="1.0" iyz="0.0" izz="1.0"/>
      </inertial>
      
      <collision>
        <origin rpy="${M_PI/2} 0 0" xyz="0 0 0"/>
        <geometry>
          <cylinder length="${wheel_length}" radius="${wheel_radius}"/>
        </geometry>
      </collision>
    </link>
    
    <gazebo reference="${parent}_${suffix}_wheel_link" >
      <mu1>35.0</mu1>
      <mu2>35.0</mu2>
      <kp>1000000000.0</kp>
      <kd>1.0</kd>
      <material>Gazebo/Black</material>
    </gazebo>
  </macro>
</robot>

